Workbook
Name Срез_Годы: #N/A
Name Срез_Период: #N/A

Sheet Отчет2

Sheet Лист5
B1: февраль | C1: март | D1: апрель | E1: май | F1: июнь | G1: июль | H1: август | I1: сентябрь | J1: октябрь | K1: ноябрь | L1: декабрь | M1: 44197 | N1: 44228 | O1: 44256 | P1: 44287 | Q1: 44317 | R1: 44348 | S1: 44378 | T1: 44409 | U1: 44440 | V1: 44470 | W1: 44501 | X1: 44531 | Y1: 44562 | Z1: 44593 | AA1: 44621 | AB1: 44652 | AC1: 44682 | AD1: 44713 | AE1: 44743 | AF1: 44774 | AG1: 44805 | AH1: 44835 | AI1: 44866 | AJ1: 44896 | AK1: 44927 | AL1: 44958 | AM1: 44986 | AN1: 45017
A2: Восточный АО | B2: 186881.6 | C2: 189676.17 | D2: 193065.69 | E2: 193645.08 | F2: 193154.91 | G2: 193771.53 | H2: 196359.5 | I2: 201082.52 | J2: 207111.72 | K2: 213064 | L2: 217457.93 | M2: 222408.36 | N2: 224060 | O2: 229760.21 | P2: 231824.1 | Q2: 236146.75 | R2: 230983.15 | S2: 239462 | T2: 243817.9 | U2: 249485.84 | V2: 253346.33 | W2: 256232 | X2: 258976.4 | Y2: 267946.63 | Z2: 270974.11 | AA2: 278463.86 | AB2: 280226.02 | AC2: 275858.13 | AD2: 272522.22 | AE2: 269980.53 | AF2: 268038.25 | AG2: 266117.44 | AH2: 261889.19 | AI2: 258588.98 | AJ2: 258297.77 | AK2: 259332.92 | AL2: 259473.59 | AM2: 259217.51 | AN2: 260149.97
A3: Западный АО | B3: 250628.75 | C3: 253823.23 | D3: 271405.14 | E3: 262902.17 | F3: 258806.72 | G3: 259270.84 | H3: 261062.06 | I3: 267512.8 | J3: 274968.23 | K3: 284145.07 | L3: 285015.18 | M3: 288669.42 | N3: 290704 | O3: 294686.3 | P3: 299003.2 | Q3: 303562.77 | R3: 307644.75 | S3: 307365.88 | T3: 313986.36 | U3: 318405.33 | V3: 321496.05 | W3: 326170 | X3: 330302.86 | Y3: 340527.34 | Z3: 346948.19 | AA3: 363085.51 | AB3: 367420.53 | AC3: 359294.43 | AD3: 348500.66 | AE3: 343912.83 | AF3: 340004.23 | AG3: 336424.3 | AH3: 330306.84 | AI3: 326518.67 | AJ3: 324768.07 | AK3: 326279.83 | AL3: 322496.15 | AM3: 325831.63 | AN3: 326518.58
A4: Новомосковский | B4: 149719.02 | C4: 149130.45 | D4: 149242.49 | E4: 149825.18 | F4: 150412.72 | G4: 152758.77 | H4: 154507.02 | I4: 159503.02 | J4: 163550.63 | K4: 166987 | L4: 168456 | M4: 174893.75 | N4: 166469 | O4: 170101.71 | P4: 171331.38 | Q4: 185143.77 | R4: 185631.43 | S4: 189270 | T4: 190978.59 | U4: 191949.76 | V4: 199505.42 | W4: 204239.19 | X4: 207782.73 | Y4: 209952.13 | Z4: 212581.94 | AA4: 221724.67 | AB4: 224159.74 | AC4: 224950.52 | AD4: 223068.02 | AE4: 218829.21 | AF4: 217394.8 | AG4: 219142.34 | AH4: 218235.14 | AI4: 213383.54 | AJ4: 213351.93 | AK4: 214267.88 | AL4: 215088.57 | AM4: 216997.25 | AN4: 216056.47
A5: Северный АО | B5: 219881.54 | C5: 221727.09 | D5: 231120.58 | E5: 226815.92 | F5: 226938.58 | G5: 225564.81 | H5: 228416.83 | I5: 233369.73 | J5: 240481.15 | K5: 248660.82 | L5: 249103.21 | M5: 254214.56 | N5: 250175 | O5: 255178.5 | P5: 262834 | Q5: 270519.52 | R5: 271639.91 | S5: 279829.87 | T5: 285267.26 | U5: 288234.29 | V5: 290471.22 | W5: 293787 | X5: 298124.97 | Y5: 301307.6 | Z5: 306540.33 | AA5: 320968.52 | AB5: 327258.35 | AC5: 321220.19 | AD5: 314573.91 | AE5: 308423.62 | AF5: 308092.56 | AG5: 307037.09 | AH5: 301857.9 | AI5: 298853.76 | AJ5: 296416.33 | AK5: 296895.24 | AL5: 297406.95 | AM5: 298460.6 | AN5: 299938.94
A6: Северо-Восточный АО | B6: 195689.13 | C6: 199279.43 | D6: 203485.71 | E6: 204127.92 | F6: 204628.72 | G6: 205183.9 | H6: 208545.58 | I6: 212295.61 | J6: 218383.83 | K6: 224126.57 | L6: 227430 | M6: 233980.95 | N6: 227817 | O6: 230654 | P6: 232671 | Q6: 242760 | R6: 250087.88 | S6: 258704 | T6: 262066.97 | U6: 267543.33 | V6: 271461.21 | W6: 275176.25 | X6: 279581.37 | Y6: 283948.77 | Z6: 287890.36 | AA6: 296364.8 | AB6: 297827.46 | AC6: 293393.43 | AD6: 294060.66 | AE6: 288945.8 | AF6: 286930.18 | AG6: 285504.27 | AH6: 281794.2 | AI6: 278597.23 | AJ6: 275840.22 | AK6: 275615.1 | AL6: 276820.28 | AM6: 277437.93 | AN6: 277858.92
A7: Северо-Западный АО | B7: 211922.93 | C7: 214557.84 | D7: 223078.79 | E7: 219803.99 | F7: 216294.95 | G7: 216240.63 | H7: 218489.13 | I7: 223895.59 | J7: 232284.88 | K7: 240315.44 | L7: 248499.86 | M7: 252079.08 | N7: 249379 | O7: 256057.23 | P7: 259971.78 | Q7: 264259.31 | R7: 263638.93 | S7: 270586.86 | T7: 273464.64 | U7: 278765.99 | V7: 285228.91 | W7: 289711.73 | X7: 292388.13 | Y7: 301531.94 | Z7: 306505.33 | AA7: 317477.8 | AB7: 317865.33 | AC7: 314491.07 | AD7: 306747.45 | AE7: 302028.76 | AF7: 301502.59 | AG7: 299742.18 | AH7: 295218.11 | AI7: 290013.11 | AJ7: 289305.57 | AK7: 290651.05 | AL7: 289313.35 | AM7: 291927 | AN7: 294542.43
A8: Троицкий | B8: 107661.93 | C8: 109808.95 | D8: 110007.16 | E8: 114759.13 | F8: 119193.29 | G8: 118866.7 | H8: 122283.19 | I8: 124611.1 | J8: 129934.96 | K8: 129043 | L8: 129358 | M8: 129570.29 | N8: 130229 | O8: 132518.89 | P8: 139459.02 | Q8: 142362.59 | R8: 143498.27 | S8: 147506.88 | T8: 151436.45 | U8: 155868.5 | V8: 157390.6 | W8: 159785.94 | X8: 161645.54 | Y8: 170210.69 | Z8: 174859.57 | AA8: 179453.84 | AB8: 179428.28 | AC8: 177505.73 | AD8: 172695.16 | AE8: 173119.7 | AF8: 173425.58 | AG8: 172950.42 | AH8: 171117.59 | AI8: 169378.69 | AJ8: 166884.06 | AK8: 166417.4 | AL8: 167266.13 | AM8: 167153.24 | AN8: 169292.3
A9: Центральный АО | B9: 435844.16 | C9: 454712.74 | D9: 506845.23 | E9: 476637.96 | F9: 473423.36 | G9: 470411.85 | H9: 473782.6 | I9: 480526.84 | J9: 485369.4 | K9: 492923.84 | L9: 492266.95 | M9: 496551.37 | N9: 485358 | O9: 506384.35 | P9: 506551.61 | Q9: 517047.08 | R9: 523622.44 | S9: 537692.18 | T9: 542877.98 | U9: 543264.81 | V9: 542715.62 | W9: 555672.41 | X9: 556712.36 | Y9: 566412.42 | Z9: 581480.32 | AA9: 614649.66 | AB9: 611145.76 | AC9: 582476.16 | AD9: 561015.96 | AE9: 560227.79 | AF9: 556845.13 | AG9: 546331.83 | AH9: 540294.96 | AI9: 537600.67 | AJ9: 536836.11 | AK9: 538747.59 | AL9: 536305.76 | AM9: 536010.64 | AN9: 543077.45
A10: Юго-Восточный АО | B10: 177566.66 | C10: 178792.09 | D10: 179632.4 | E10: 180106.26 | F10: 180518.92 | G10: 181588.46 | H10: 183216.86 | I10: 187103.09 | J10: 193257.31 | K10: 198357.59 | L10: 204423.54 | M10: 207722.83 | N10: 208923 | O10: 214923.25 | P10: 214656 | Q10: 223160.26 | R10: 221907.46 | S10: 231525.02 | T10: 236217.44 | U10: 240456.28 | V10: 244291.87 | W10: 248434.7 | X10: 250776.5 | Y10: 257687.7 | Z10: 262051.62 | AA10: 270818.45 | AB10: 273327.72 | AC10: 270054.67 | AD10: 265723.44 | AE10: 263884.02 | AF10: 263479.18 | AG10: 262155.1 | AH10: 259166.25 | AI10: 255999.52 | AJ10: 253290.12 | AK10: 252980.29 | AL10: 252497.74 | AM10: 251723.64 | AN10: 253205.29
A11: Юго-Западный АО | B11: 219292.48 | C11: 220515.76 | D11: 225259.64 | E11: 224658.72 | F11: 223714.35 | G11: 224034.03 | H11: 225873.27 | I11: 231188.57 | J11: 238795.99 | K11: 242855.65 | L11: 251075.41 | M11: 252676.77 | N11: 251521 | O11: 257717.4 | P11: 263055.17 | Q11: 267496.64 | R11: 267714.09 | S11: 274500.02 | T11: 279971.03 | U11: 284425.1 | V11: 287414.24 | W11: 291686.34 | X11: 295671.38 | Y11: 301752.71 | Z11: 307307.37 | AA11: 320210.03 | AB11: 324283.56 | AC11: 318190.27 | AD11: 312344.65 | AE11: 309244.13 | AF11: 308834.38 | AG11: 306233.12 | AH11: 301531.72 | AI11: 299035.42 | AJ11: 296629.69 | AK11: 295773.72 | AL11: 294978.52 | AM11: 293915.58 | AN11: 295572.76
A12: Южный АО | B12: 194781.37 | C12: 196955.88 | D12: 198242.43 | E12: 198537.21 | F12: 197965.85 | G12: 198828.69 | H12: 201862.54 | I12: 206029.5 | J12: 213104.89 | K12: 220071.71 | L12: 224172.18 | M12: 229702.25 | N12: 227762 | O12: 235586.81 | P12: 240115.28 | Q12: 243481.25 | R12: 238147.17 | S12: 251078.99 | T12: 255337.31 | U12: 257160.38 | V12: 260881.01 | W12: 265469.07 | X12: 271211.71 | Y12: 276059.7 | Z12: 279253.83 | AA12: 289946.49 | AB12: 293908.63 | AC12: 290264.33 | AD12: 285898.24 | AE12: 283666.13 | AF12: 282502.13 | AG12: 283201.7 | AH12: 278112.62 | AI12: 274615.69 | AJ12: 272147.78 | AK12: 271771.28 | AL12: 271944.72 | AM12: 271339.63 | AN12: 271537.54
B15: кол-во
A16: Восточный АО | B16: 5111
A17: Западный АО | B17: 5624
A18: Зеленоградский АО | B18: 697
A19: Новомосковский | B19: 1776
A20: Северный АО | B20: 5135
A21: Северо-Восточный АО | B21: 4709
A22: Северо-Западный АО | B22: 3148
A23: Троицкий | B23: 632
A24: Центральный АО | B24: 6266
A25: Юго-Восточный АО | B25: 5061
A26: Юго-Западный АО | B26: 5388
A27: Южный АО | B27: 5270

Sheet Свод изменений
B1: Изменение объема относительно прошлого месяца
C2: Год | D2: Период | E2: Значения
C3: 2020 | Y3: 2021 | AW3: 2022 | BU3: 2023 | CS3: 2024 | DQ3: 2025
C4: фев | E4: мар | G4: апр | I4: май | K4: июн | M4: июл | O4: авг | Q4: сен | S4: окт | U4: ноя | W4: дек | Y4: янв | AA4: фев | AC4: мар | AE4: апр | AG4: май | AI4: июн | AK4: июл | AM4: авг | AO4: сен | AQ4: окт | AS4: ноя | AU4: дек | AW4: янв | AY4: фев | BA4: мар | BC4: апр | BE4: май | BG4: июн | BI4: июл | BK4: авг | BM4: сен | BO4: окт | BQ4: ноя | BS4: дек | BU4: янв | BW4: фев | BY4: мар | CA4: апр | CC4: май | CE4: июн | CG4: июл | CI4: авг | CK4: сен | CM4: окт | CO4: ноя | CQ4: дек | CS4: янв | CU4: фев | CW4: мар | CY4: апр | DA4: май | DC4: июн | DE4: июл | DG4: авг | DI4: сен | DK4: окт | DM4: ноя | DO4: дек | DQ4: янв | DS4: фев | DU4: мар | DW4: апр | DY4: май | EA4: июн | EC4: июл | EE4: авг
B5: Округ | C5: Объем | D5: Изм объема | E5: Объем | F5: Изм объема | G5: Объем | H5: Изм объема | I5: Объем | J5: Изм объема | K5: Объем | L5: Изм объема | M5: Объем | N5: Изм объема | O5: Объем | P5: Изм объема | Q5: Объем | R5: Изм объема | S5: Объем | T5: Изм объема | U5: Объем | V5: Изм объема | W5: Объем | X5: Изм объема | Y5: Объем | Z5: Изм объема | AA5: Объем | AB5: Изм объема | AC5: Объем | AD5: Изм объема | AE5: Объем | AF5: Изм объема | AG5: Объем | AH5: Изм объема | AI5: Объем | AJ5: Изм объема | AK5: Объем | AL5: Изм объема | AM5: Объем | AN5: Изм объема | AO5: Объем | AP5: Изм объема | AQ5: Объем | AR5: Изм объема | AS5: Объем | AT5: Изм объема | AU5: Объем | AV5: Изм объема | AW5: Объем | AX5: Изм объема | AY5: Объем | AZ5: Изм объема | BA5: Объем | BB5: Изм объема | BC5: Объем | BD5: Изм объема | BE5: Объем | BF5: Изм объема | BG5: Объем | BH5: Изм объема | BI5: Объем | BJ5: Изм объема | BK5: Объем | BL5: Изм объема | BM5: Объем | BN5: Изм объема | BO5: Объем | BP5: Изм объема | BQ5: Объем | BR5: Изм объема | BS5: Объем | BT5: Изм объема | BU5: Объем | BV5: Изм объема | BW5: Объем | BX5: Изм объема | BY5: Объем | BZ5: Изм объема | CA5: Объем | CB5: Изм объема | CC5: Объем | CD5: Изм объема | CE5: Объем | CF5: Изм объема | CG5: Объем | CH5: Изм объема | CI5: Объем | CJ5: Изм объема | CK5: Объем | CL5: Изм объема | CM5: Объем | CN5: Изм объема | CO5: Объем | CP5: Изм объема | CQ5: Объем | CR5: Изм объема | CS5: Объем | CT5: Изм объема | CU5: Объем | CV5: Изм объема | CW5: Объем | CX5: Изм объема | CY5: Объем | CZ5: Изм объема | DA5: Объем | DB5: Изм объема | DC5: Объем | DD5: Изм объема | DE5: Объем | DF5: Изм объема | DG5: Объем | DH5: Изм объема | DI5: Объем | DJ5: Изм объема | DK5: Объем | DL5: Изм объема | DM5: Объем | DN5: Изм объема | DO5: Объем | DP5: Изм объема | DQ5: Объем | DR5: Изм объема | DS5: Объем | DT5: Изм объема | DU5: Объем | DV5: Изм объема | DW5: Объем | DX5: Изм объема | DY5: Объем | DZ5: Изм объема | EA5: Объем | EB5: Изм объема | EC5: Объем | ED5: Изм объема | EE5: Объем | EF5: Изм объема
B6: Восточный | C6: 4978 | D6: 0 | E6: 4751 | F6: -0.045600643 | G6: 3184 | H6: -0.3298253 | I6: 3693 | J6: 0.15986181 | K6: 4359 | L6: 0.18034119 | M6: 4398 | N6: 0.0089470062 | O6: 4406 | P6: 0.0018190086 | Q6: 4412 | R6: 0.0013617794 | S6: 4141 | T6: -0.061423391 | U6: 3694 | V6: -0.10794494 | W6: 3285 | X6: -0.11072009 | Y6: 3195 | Z6: -0.02739726 | AA6: 3591 | AB6: 0.12394366 | AC6: 3899.49 | AD6: 0.085906433 | AE6: 3817 | AF6: -0.021154048 | AG6: 3810 | AH6: -0.001833901 | AI6: 4015 | AJ6: 0.053805774 | AK6: 3909 | AL6: -0.026400996 | AM6: 3911 | AN6: 0.00051163981 | AO6: 4049 | AP6: 0.035285093 | AQ6: 4337 | AR6: 0.071128674 | AS6: 4287 | AT6: -0.011528706 | AU6: 4143 | AV6: -0.033589923 | AW6: 3736 | AX6: -0.098237992 | AY6: 4066 | AZ6: 0.088329764 | BA6: 3814 | BB6: -0.061977373 | BC6: 3544 | BD6: -0.07079182 | BE6: 3839 | BF6: 0.083239278 | BG6: 4363 | BH6: 0.13649388 | BI6: 4660 | BJ6: 0.068072427 | BK6: 4854 | BL6: 0.041630901 | BM6: 5392 | BN6: 0.11083642 | BO6: 5520 | BP6: 0.023738872 | BQ6: 5411 | BR6: -0.019746377 | BS6: 5176 | BT6: -0.04343005 | BU6: 4868 | BV6: -0.05950541 | BW6: 5206 | BX6: 0.069433032 | BY6: 5434 | BZ6: 0.04379562 | CA6: 5111 | CB6: -0.059440559 | CC6: 4977 | CD6: -0.026217961 | CE6: 4803 | CF6: -0.03496082 | CG6: 4490 | CH6: -0.065167604 | CI6: 4217 | CJ6: -0.060801782 | CK6: 4035 | CL6: -0.043158644 | CM6: 3969 | CN6: -0.016356877 | CO6: 3959 | CP6: -0.0025195263 | CQ6: 3579 | CR6: -0.095983834 | CS6: 3611 | CT6: 0.008941045 | CU6: 4098 | CV6: 0.13486569 | CW6: 4345 | CX6: 0.060273304 | CY6: 4504 | CZ6: 0.036593786 | DA6: 4588 | DB6: 0.018650089 | DC6: 4665 | DD6: 0.016782912 | DE6: 4661 | DF6: -0.00085744909 | DG6: 4820 | DH6: 0.034112851 | DI6: 4873 | DJ6: 0.010995851 | DK6: 4960.52 | DL6: 0.017960189 | DM6: 4960 | DN6: -0.00010482772 | DO6: 4286 | DP6: -0.1358871 | DQ6: 3874 | DR6: -0.096126925 | DS6: 3995 | DT6: 0.031233867 | DU6: 4031 | DV6: 0.0090112641 | DW6: 3945 | DX6: -0.021334656 | DY6: 3937 | DZ6: -0.0020278834 | EA6: 3717 | EB6: -0.055880112 | EC6: 3894 | ED6: 0.047619048 | EE6: 3771 | EF6: -0.031587057
B7: Западный | C7: 6871 | D7: 0 | E7: 6539 | F7: -0.048319022 | G7: 4784 | H7: -0.26838966 | I7: 5340 | J7: 0.11622074 | K7: 5910 | L7: 0.10674157 | M7: 5846 | N7: -0.010829103 | O7: 5723 | P7: -0.021040027 | Q7: 5422 | R7: -0.052594793 | S7: 5134 | T7: -0.053116931 | U7: 4691 | V7: -0.086287495 | W7: 4250 | X7: -0.094009806 | Y7: 4300 | Z7: 0.011764706 | AA7: 4594 | AB7: 0.068372093 | AC7: 4920.16 | AD7: 0.070996953 | AE7: 4885 | AF7: -0.0071461091 | AG7: 4742 | AH7: -0.029273286 | AI7: 4716 | AJ7: -0.0054829186 | AK7: 4686 | AL7: -0.0063613232 | AM7: 4497 | AN7: -0.040332907 | AO7: 4608 | AP7: 0.024683122 | AQ7: 4784 | AR7: 0.038194444 | AS7: 4565 | AT7: -0.045777592 | AU7: 4438 | AV7: -0.027820372 | AW7: 4084 | AX7: -0.07976566 | AY7: 4474 | AZ7: 0.095494613 | BA7: 4342 | BB7: -0.0295038 | BC7: 3957 | BD7: -0.088668816 | BE7: 4248 | BF7: 0.073540561 | BG7: 4886 | BH7: 0.15018832 | BI7: 5282 | BJ7: 0.081047892 | BK7: 5343 | BL7: 0.011548656 | BM7: 5886 | BN7: 0.1016283 | BO7: 6034 | BP7: 0.02514441 | BQ7: 5864 | BR7: -0.028173682 | BS7: 5684 | BT7: -0.030695771 | BU7: 5442 | BV7: -0.042575651 | BW7: 5638 | BX7: 0.036016171 | BY7: 5901 | BZ7: 0.046647747 | CA7: 5624 | CB7: -0.046941196 | CC7: 5481 | CD7: -0.025426743 | CE7: 5316 | CF7: -0.030103996 | CG7: 4966 | CH7: -0.065838977 | CI7: 4721 | CJ7: -0.049335481 | CK7: 4516 | CL7: -0.043423004 | CM7: 4334 | CN7: -0.040301151 | CO7: 4372 | CP7: 0.0087678819 | CQ7: 4021 | CR7: -0.080283623 | CS7: 4015 | CT7: -0.0014921661 | CU7: 4441 | CV7: 0.10610212 | CW7: 4535 | CX7: 0.021166404 | CY7: 4636 | CZ7: 0.022271224 | DA7: 4632 | DB7: -0.00086281277 | DC7: 4673 | DD7: 0.008851468 | DE7: 4621 | DF7: -0.011127755 | DG7: 4673 | DH7: 0.011252976 | DI7: 4721 | DJ7: 0.010271774 | DK7: 4821.42 | DL7: 0.021270917 | DM7: 4833 | DN7: 0.002401782 | DO7: 4408 | DP7: -0.087937099 | DQ7: 4008 | DR7: -0.090744102 | DS7: 4055 | DT7: 0.011726547 | DU7: 4060 | DV7: 0.0012330456 | DW7: 4053 | DX7: -0.0017241379 | DY7: 4124 | DZ7: 0.017517888 | EA7: 3981 | EB7: -0.034675073 | EC7: 4124 | ED7: 0.035920623 | EE7: 4115 | EF7: -0.0021823472
B8: Новомосковский | C8: 904 | D8: 0 | E8: 820 | F8: -0.092920354 | G8: 619 | H8: -0.24512195 | I8: 725 | J8: 0.17124394 | K8: 835 | L8: 0.15172414 | M8: 734 | N8: -0.12095808 | O8: 686 | P8: -0.065395095 | Q8: 690 | R8: 0.0058309038 | S8: 667 | T8: -0.033333333 | U8: 555 | V8: -0.16791604 | W8: 402 | X8: -0.27567568 | Y8: 1004 | Z8: 1.4975124 | AA8: 1045 | AB8: 0.040836653 | AC8: 1120.05 | AD8: 0.071818182 | AE8: 1150 | AF8: 0.026739878 | AG8: 998 | AH8: -0.13217391 | AI8: 1045 | AJ8: 0.047094188 | AK8: 1083 | AL8: 0.036363636 | AM8: 1029 | AN8: -0.049861496 | AO8: 1036 | AP8: 0.0068027211 | AQ8: 1172 | AR8: 0.13127413 | AS8: 1255 | AT8: 0.070819113 | AU8: 1214 | AV8: -0.032669323 | AW8: 1018 | AX8: -0.16144975 | AY8: 1187 | AZ8: 0.16601179 | BA8: 1035 | BB8: -0.12805392 | BC8: 893 | BD8: -0.13719807 | BE8: 963 | BF8: 0.078387458 | BG8: 1088 | BH8: 0.1298027 | BI8: 1210 | BJ8: 0.11213235 | BK8: 1262 | BL8: 0.042975207 | BM8: 1442 | BN8: 0.14263074 | BO8: 1461 | BP8: 0.013176144 | BQ8: 1383 | BR8: -0.05338809 | BS8: 1450 | BT8: 0.048445409 | BU8: 1426 | BV8: -0.016551724 | BW8: 1521 | BX8: 0.066619916 | BY8: 1674 | BZ8: 0.10059172 | CA8: 1776 | CB8: 0.0609319 | CC8: 1781 | CD8: 0.0028153153 | CE8: 1846 | CF8: 0.03649635 | CG8: 1713 | CH8: -0.072047671 | CI8: 1650 | CJ8: -0.036777583 | CK8: 1548 | CL8: -0.061818182 | CM8: 1537 | CN8: -0.0071059432 | CO8: 1498 | CP8: -0.025374105 | CQ8: 1372 | CR8: -0.08411215 | CS8: 1330 | CT8: -0.030612245 | CU8: 1528 | CV8: 0.14887218 | CW8: 1552 | CX8: 0.015706806 | CY8: 1552 | CZ8: 0 | DA8: 1532 | DB8: -0.012886598 | DC8: 2308 | DD8: 0.50652742 | DE8: 3477 | DF8: 0.50649913 | DG8: 3926 | DH8: 0.12913431 | DI8: 3468 | DJ8: -0.11665818 | DK8: 3478.57 | DL8: 0.0030478662 | DM8: 3174 | DN8: -0.087556093 | DO8: 2419 | DP8: -0.2378702 | DQ8: 2007 | DR8: -0.17031831 | DS8: 2021 | DT8: 0.0069755855 | DU8: 1979 | DV8: -0.020781791 | DW8: 1946 | DX8: -0.016675088 | DY8: 1912 | DZ8: -0.017471737 | EA8: 1678 | EB8: -0.12238494 | EC8: 1473 | ED8: -0.12216925 | EE8: 1327 | EF8: -0.099117447
B9: Северный | C9: 5244 | D9: 0 | E9: 5076 | F9: -0.032036613 | G9: 3608 | H9: -0.2892041 | I9: 4110 | J9: 0.13913525 | K9: 4639 | L9: 0.12871046 | M9: 4557 | N9: -0.017676223 | O9: 4338 | P9: -0.048057933 | Q9: 4169 | R9: -0.038958045 | S9: 3988 | T9: -0.043415687 | U9: 3591 | V9: -0.099548646 | W9: 3271 | X9: -0.089111668 | Y9: 3263 | Z9: -0.0024457352 | AA9: 3674 | AB9: 0.12595771 | AC9: 3931.1 | AD9: 0.069978225 | AE9: 3958 | AF9: 0.0068428684 | AG9: 3991 | AH9: 0.0083375442 | AI9: 3984 | AJ9: -0.0017539464 | AK9: 3998 | AL9: 0.0035140562 | AM9: 3932 | AN9: -0.016508254 | AO9: 4049.96 | AP9: 0.03 | AQ9: 3949 | AR9: -0.024928641 | AS9: 3838 | AT9: -0.028108382 | AU9: 3729 | AV9: -0.028400208 | AW9: 3454 | AX9: -0.073746313 | AY9: 3790 | AZ9: 0.097278518 | BA9: 3672 | BB9: -0.031134565 | BC9: 3319 | BD9: -0.096132898 | BE9: 3715 | BF9: 0.11931305 | BG9: 4146 | BH9: 0.11601615 | BI9: 4412 | BJ9: 0.064158225 | BK9: 4509 | BL9: 0.021985494 | BM9: 4984 | BN9: 0.10534487 | BO9: 5141 | BP9: 0.031500803 | BQ9: 5135 | BR9: -0.0011670881 | BS9: 5116 | BT9: -0.0037000974 | BU9: 5001 | BV9: -0.022478499 | BW9: 5188 | BX9: 0.037392521 | BY9: 5408 | BZ9: 0.042405551 | CA9: 5135 | CB9: -0.050480769 | CC9: 4966 | CD9: -0.032911392 | CE9: 4837 | CF9: -0.025976641 | CG9: 4496 | CH9: -0.070498243 | CI9: 4167 | CJ9: -0.073176157 | CK9: 3942 | CL9: -0.05399568 | CM9: 3857 | CN9: -0.021562659 | CO9: 3813 | CP9: -0.01140783 | CQ9: 3514 | CR9: -0.078415945 | CS9: 3513 | CT9: -0.00028457598 | CU9: 4039 | CV9: 0.14972958 | CW9: 4273 | CX9: 0.057935132 | CY9: 4324 | CZ9: 0.011935408 | DA9: 4222 | DB9: -0.023589269 | DC9: 4288 | DD9: 0.015632402 | DE9: 4257 | DF9: -0.0072294776 | DG9: 4213 | DH9: -0.010335917 | DI9: 4308 | DJ9: 0.022549252 | DK9: 4441.57 | DL9: 0.031005107 | DM9: 4324 | DN9: -0.02647037 | DO9: 3836 | DP9: -0.11285846 | DQ9: 3469 | DR9: -0.095672576 | DS9: 3577 | DT9: 0.031132891 | DU9: 3676 | DV9: 0.027676824 | DW9: 3600 | DX9: -0.020674646 | DY9: 3642 | DZ9: 0.011666667 | EA9: 3479 | EB9: -0.044755629 | EC9: 3606 | ED9: 0.036504743 | EE9: 3596 | EF9: -0.0027731559
B10: Северо-Восточный | C10: 5331 | D10: 0 | E10: 5014 | F10: -0.059463515 | G10: 3381 | H10: -0.32568807 | I10: 3845 | J10: 0.1372375 | K10: 4374 | L10: 0.13758127 | M10: 4320 | N10: -0.012345679 | O10: 4320 | P10: 0 | Q10: 4126 | R10: -0.044907407 | S10: 3863 | T10: -0.063742123 | U10: 3504 | V10: -0.092932954 | W10: 3212 | X10: -0.083333333 | Y10: 3218 | Z10: 0.001867995 | AA10: 3538 | AB10: 0.099440646 | AC10: 3772.45 | AD10: 0.066266252 | AE10: 3777 | AF10: 0.0012061127 | AG10: 3734 | AH10: -0.011384697 | AI10: 3643 | AJ10: -0.024370648 | AK10: 3669 | AL10: 0.007136975 | AM10: 3694 | AN10: 0.0068138457 | AO10: 3908 | AP10: 0.057931781 | AQ10: 4163 | AR10: 0.065250768 | AS10: 3956 | AT10: -0.049723757 | AU10: 3794 | AV10: -0.040950455 | AW10: 3524 | AX10: -0.071164997 | AY10: 3808 | AZ10: 0.080590238 | BA10: 3632 | BB10: -0.046218487 | BC10: 3131 | BD10: -0.13794053 | BE10: 3500 | BF10: 0.11785372 | BG10: 4008 | BH10: 0.14514286 | BI10: 4259 | BJ10: 0.06262475 | BK10: 4356 | BL10: 0.022775299 | BM10: 4848 | BN10: 0.11294766 | BO10: 5071 | BP10: 0.04599835 | BQ10: 4985 | BR10: -0.01695918 | BS10: 4728 | BT10: -0.051554664 | BU10: 4540 | BV10: -0.039763113 | BW10: 4691 | BX10: 0.033259912 | BY10: 5008 | BZ10: 0.06757621 | CA10: 4709 | CB10: -0.059704473 | CC10: 4642 | CD10: -0.014228074 | CE10: 4484 | CF10: -0.034037053 | CG10: 4116 | CH10: -0.082069581 | CI10: 3883 | CJ10: -0.056608358 | CK10: 3659 | CL10: -0.057687355 | CM10: 3624 | CN10: -0.009565455 | CO10: 3725 | CP10: 0.027869757 | CQ10: 3379 | CR10: -0.092885906 | CS10: 3468 | CT10: 0.026339154 | CU10: 3779 | CV10: 0.089677047 | CW10: 3891 | CX10: 0.02963747 | CY10: 3960 | CZ10: 0.017733231 | DA10: 3978 | DB10: 0.0045454545 | DC10: 4056 | DD10: 0.019607843 | DE10: 3997 | DF10: -0.014546351 | DG10: 4129 | DH10: 0.033024769 | DI10: 4236 | DJ10: 0.025914265 | DK10: 4393.42 | DL10: 0.037162417 | DM10: 4381 | DN10: -0.0028269549 | DO10: 3781 | DP10: -0.13695503 | DQ10: 3397 | DR10: -0.10156043 | DS10: 3476 | DT10: 0.023255814 | DU10: 3467 | DV10: -0.002589183 | DW10: 3406 | DX10: -0.017594462 | DY10: 3420 | DZ10: 0.0041103934 | EA10: 3280 | EB10: -0.040935673 | EC10: 3406 | ED10: 0.038414634 | EE10: 3408 | EF10: 0.00058719906
B11: Северо-Западный | C11: 3139 | D11: 0 | E11: 3084 | F11: -0.017521504 | G11: 2134 | H11: -0.3080415 | I11: 2384 | J11: 0.11715089 | K11: 2802 | L11: 0.17533557 | M11: 2834 | N11: 0.011420414 | O11: 2681 | P11: -0.053987297 | Q11: 2541 | R11: -0.052219321 | S11: 2408 | T11: -0.052341598 | U11: 2275 | V11: -0.055232558 | W11: 2059 | X11: -0.094945055 | Y11: 2011 | Z11: -0.023312288 | AA11: 2316 | AB11: 0.15166584 | AC11: 2399.7 | AD11: 0.036139896 | AE11: 2340 | AF11: -0.02487811 | AG11: 2330 | AH11: -0.0042735043 | AI11: 2457 | AJ11: 0.054506438 | AK11: 2411 | AL11: -0.018722019 | AM11: 2442 | AN11: 0.012857735 | AO11: 2514 | AP11: 0.029484029 | AQ11: 2540 | AR11: 0.010342084 | AS11: 2434 | AT11: -0.041732283 | AU11: 2334 | AV11: -0.041084634 | AW11: 2076 | AX11: -0.11053985 | AY11: 2350 | AZ11: 0.13198459 | BA11: 2221 | BB11: -0.054893617 | BC11: 2045 | BD11: -0.079243584 | BE11: 2324 | BF11: 0.13643032 | BG11: 2578 | BH11: 0.10929432 | BI11: 2799 | BJ11: 0.085725369 | BK11: 2901 | BL11: 0.036441586 | BM11: 3264 | BN11: 0.12512927 | BO11: 3390 | BP11: 0.038602941 | BQ11: 3374 | BR11: -0.004719764 | BS11: 3261 | BT11: -0.033491405 | BU11: 3060 | BV11: -0.061637534 | BW11: 3207 | BX11: 0.048039216 | BY11: 3337 | BZ11: 0.040536327 | CA11: 3148 | CB11: -0.056637699 | CC11: 2995 | CD11: -0.048602287 | CE11: 2857 | CF11: -0.046076795 | CG11: 2689 | CH11: -0.05880294 | CI11: 2507 | CJ11: -0.067683154 | CK11: 2374 | CL11: -0.053051456 | CM11: 2255 | CN11: -0.050126369 | CO11: 2403 | CP11: 0.065631929 | CQ11: 2227 | CR11: -0.073241781 | CS11: 2268 | CT11: 0.018410418 | CU11: 2574 | CV11: 0.13492063 | CW11: 2758 | CX11: 0.071484071 | CY11: 2807 | CZ11: 0.017766497 | DA11: 2760 | DB11: -0.016743855 | DC11: 2845 | DD11: 0.030797101 | DE11: 2823 | DF11: -0.0077328647 | DG11: 2777 | DH11: -0.016294722 | DI11: 2881 | DJ11: 0.037450486 | DK11: 2996 | DL11: 0.039916696 | DM11: 2898 | DN11: -0.03271028 | DO11: 2615 | DP11: -0.097653554 | DQ11: 2373 | DR11: -0.092543021 | DS11: 2462 | DT11: 0.037505268 | DU11: 2467 | DV11: 0.0020308692 | DW11: 2420 | DX11: -0.01905148 | DY11: 2404 | DZ11: -0.0066115702 | EA11: 2190 | EB11: -0.089018303 | EC11: 2255 | ED11: 0.029680365 | EE11: 2270 | EF11: 0.0066518847
B12: Троицкий | C12: 183 | D12: 0 | E12: 152 | F12: -0.16939891 | G12: 101 | H12: -0.33552632 | I12: 108 | J12: 0.069306931 | K12: 133 | L12: 0.23148148 | M12: 153 | N12: 0.15037594 | O12: 155 | P12: 0.013071895 | Q12: 152 | R12: -0.019354839 | S12: 143 | T12: -0.059210526 | U12: 128 | V12: -0.1048951 | W12: 0 | X12: 0 | Y12: 366 | Z12: 0 | AA12: 395 | AB12: 0.079234973 | AC12: 413.25 | AD12: 0.046202532 | AE12: 422 | AF12: 0.021173624 | AG12: 473 | AH12: 0.12085308 | AI12: 490 | AJ12: 0.035940803 | AK12: 480 | AL12: -0.020408163 | AM12: 477 | AN12: -0.00625 | AO12: 528 | AP12: 0.10691824 | AQ12: 530 | AR12: 0.0037878788 | AS12: 476 | AT12: -0.10188679 | AU12: 465 | AV12: -0.023109244 | AW12: 435 | AX12: -0.064516129 | AY12: 462 | AZ12: 0.062068966 | BA12: 491 | BB12: 0.062770563 | BC12: 430 | BD12: -0.12423625 | BE12: 505 | BF12: 0.1744186 | BG12: 558 | BH12: 0.1049505 | BI12: 597 | BJ12: 0.069892473 | BK12: 613 | BL12: 0.02680067 | BM12: 649 | BN12: 0.058727569 | BO12: 653 | BP12: 0.0061633282 | BQ12: 652 | BR12: -0.0015313936 | BS12: 632 | BT12: -0.030674847 | BU12: 590 | BV12: -0.066455696 | BW12: 639 | BX12: 0.083050847 | BY12: 677 | BZ12: 0.059467919 | CA12: 632 | CB12: -0.066469719 | CC12: 641 | CD12: 0.014240506 | CE12: 616 | CF12: -0.03900156 | CG12: 600 | CH12: -0.025974026 | CI12: 611 | CJ12: 0.018333333 | CK12: 579 | CL12: -0.052373159 | CM12: 560 | CN12: -0.032815199 | CO12: 574 | CP12: 0.025 | CQ12: 531 | CR12: -0.074912892 | CS12: 543 | CT12: 0.02259887 | CU12: 597 | CV12: 0.099447514 | CW12: 626 | CX12: 0.048576214 | CY12: 600 | CZ12: -0.041533546 | DA12: 567 | DB12: -0.055 | DC12: 584 | DD12: 0.029982363 | DE12: 720 | DF12: 0.23287671 | DG12: 802 | DH12: 0.11388889 | DI12: 783 | DJ12: -0.023690773 | DK12: 761.84 | DL12: -0.027024266 | DM12: 765 | DN12: 0.0041478526 | DO12: 642 | DP12: -0.16078431 | DQ12: 598 | DR12: -0.068535826 | DS12: 590 | DT12: -0.013377926 | DU12: 587 | DV12: -0.0050847458 | DW12: 578 | DX12: -0.015332198 | DY12: 587 | DZ12: 0.015570934 | EA12: 543 | EB12: -0.074957411 | EC12: 571 | ED12: 0.051565378 | EE12: 545 | EF12: -0.045534151
B13: Центральный | C13: 8180 | D13: 0 | E13: 8128 | F13: -0.0063569682 | G13: 7125 | H13: -0.12340059 | I13: 7471 | J13: 0.048561404 | K13: 7449 | L13: -0.0029447196 | M13: 7266 | N13: -0.024567056 | O13: 7104 | P13: -0.022295623 | Q13: 7049 | R13: -0.0077421171 | S13: 6784 | T13: -0.037593985 | U13: 6356 | V13: -0.063089623 | W13: 6021 | X13: -0.052706104 | Y13: 5911 | Z13: -0.01826939 | AA13: 6167 | AB13: 0.043309085 | AC13: 6806.7 | AD13: 0.10372953 | AE13: 6750 | AF13: -0.0083300278 | AG13: 6427 | AH13: -0.047851852 | AI13: 6281 | AJ13: -0.022716664 | AK13: 6230 | AL13: -0.0081197262 | AM13: 5895 | AN13: -0.053772071 | AO13: 6071.85 | AP13: 0.03 | AQ13: 5722 | AR13: -0.057618354 | AS13: 5276 | AT13: -0.077944775 | AU13: 5051 | AV13: -0.042645944 | AW13: 4645 | AX13: -0.080380123 | AY13: 4969 | AZ13: 0.069752422 | BA13: 4989 | BB13: 0.0040249547 | BC13: 4684 | BD13: -0.061134496 | BE13: 5078 | BF13: 0.08411614 | BG13: 5504 | BH13: 0.083891296 | BI13: 5763 | BJ13: 0.047056686 | BK13: 5700 | BL13: -0.010931806 | BM13: 6098 | BN13: 0.069824561 | BO13: 6450 | BP13: 0.057723844 | BQ13: 6518 | BR13: 0.010542636 | BS13: 6326 | BT13: -0.029456889 | BU13: 6012 | BV13: -0.049636421 | BW13: 6277 | BX13: 0.04407851 | BY13: 6617 | BZ13: 0.054166003 | CA13: 6266 | CB13: -0.053045187 | CC13: 6052 | CD13: -0.034152569 | CE13: 5945 | CF13: -0.017680106 | CG13: 5708 | CH13: -0.039865433 | CI13: 5480 | CJ13: -0.039943938 | CK13: 5223 | CL13: -0.04689781 | CM13: 5134 | CN13: -0.017040015 | CO13: 5021 | CP13: -0.022010129 | CQ13: 4644 | CR13: -0.075084644 | CS13: 4523 | CT13: -0.026055125 | CU13: 4969 | CV13: 0.098607119 | CW13: 5057 | CX13: 0.017709801 | CY13: 5086 | CZ13: 0.0057346253 | DA13: 4908 | DB13: -0.034998034 | DC13: 5056 | DD13: 0.030154849 | DE13: 5069 | DF13: 0.0025712025 | DG13: 5117 | DH13: 0.0094693233 | DI13: 5198 | DJ13: 0.015829588 | DK13: 5519.06 | DL13: 0.061766064 | DM13: 5599 | DN13: 0.014484351 | DO13: 5113 | DP13: -0.086801215 | DQ13: 4645 | DR13: -0.091531391 | DS13: 4680 | DT13: 0.0075349839 | DU13: 4783 | DV13: 0.022008547 | DW13: 4702 | DX13: -0.016934978 | DY13: 4706 | DZ13: 0.00085070183 | EA13: 4414 | EB13: -0.062048449 | EC13: 4498 | ED13: 0.019030358 | EE13: 4466 | EF13: -0.007114273
B14: Юго-Восточный | C14: 5183 | D14: 0 | E14: 5066 | F14: -0.022573799 | G14: 3358 | H14: -0.33714962 | I14: 3793 | J14: 0.12954139 | K14: 4640 | L14: 0.22330609 | M14: 4622 | N14: -0.0038793103 | O14: 4602 | P14: -0.0043271311 | Q14: 4600 | R14: -0.00043459365 | S14: 4215 | T14: -0.083695652 | U14: 3865 | V14: -0.083036773 | W14: 3549 | X14: -0.081759379 | Y14: 3518 | Z14: -0.0087348549 | AA14: 3842 | AB14: 0.092097783 | AC14: 4237.52 | AD14: 0.10294638 | AE14: 4121 | AF14: -0.027497215 | AG14: 4149 | AH14: 0.0067944674 | AI14: 4061 | AJ14: -0.02120993 | AK14: 4012 | AL14: -0.012065994 | AM14: 3774 | AN14: -0.059322034 | AO14: 3827 | AP14: 0.014043455 | AQ14: 4050 | AR14: 0.058270186 | AS14: 3936 | AT14: -0.028148148 | AU14: 3787 | AV14: -0.037855691 | AW14: 3421 | AX14: -0.096646422 | AY14: 3763 | AZ14: 0.099970769 | BA14: 3548 | BB14: -0.057135264 | BC14: 3190 | BD14: -0.10090192 | BE14: 3566 | BF14: 0.11786834 | BG14: 4048 | BH14: 0.13516545 | BI14: 4381 | BJ14: 0.082262846 | BK14: 4489 | BL14: 0.024651906 | BM14: 4962 | BN14: 0.10536868 | BO14: 5129 | BP14: 0.033655784 | BQ14: 5121 | BR14: -0.0015597582 | BS14: 4901 | BT14: -0.042960359 | BU14: 4681 | BV14: -0.044888798 | BW14: 5084 | BX14: 0.086092715 | BY14: 5343 | BZ14: 0.050944138 | CA14: 5061 | CB14: -0.052779337 | CC14: 5004 | CD14: -0.011262596 | CE14: 4873 | CF14: -0.026179057 | CG14: 4668 | CH14: -0.042068541 | CI14: 4454 | CJ14: -0.045844045 | CK14: 4111 | CL14: -0.07700943 | CM14: 3868 | CN14: -0.059109706 | CO14: 3932 | CP14: 0.016546019 | CQ14: 3549 | CR14: -0.0974059 | CS14: 3507 | CT14: -0.01183432 | CU14: 3955 | CV14: 0.12774451 | CW14: 4108 | CX14: 0.038685209 | CY14: 4256 | CZ14: 0.036027264 | DA14: 4282 | DB14: 0.0061090226 | DC14: 4308 | DD14: 0.006071929 | DE14: 4403 | DF14: 0.022051996 | DG14: 4341 | DH14: -0.014081308 | DI14: 4512 | DJ14: 0.039391845 | DK14: 4558.2 | DL14: 0.010239362 | DM14: 4512 | DN14: -0.01013558 | DO14: 3871 | DP14: -0.1420656 | DQ14: 3480 | DR14: -0.10100749 | DS14: 3564 | DT14: 0.024137931 | DU14: 3757 | DV14: 0.054152637 | DW14: 3640 | DX14: -0.031141869 | DY14: 3673 | DZ14: 0.0090659341 | EA14: 3446 | EB14: -0.061802341 | EC14: 3544 | ED14: 0.02843877 | EE14: 3588 | EF14: 0.01241535
B15: Юго-Западный | C15: 5809 | D15: 0 | E15: 5714 | F15: -0.016353934 | G15: 3932 | H15: -0.31186559 | I15: 4502 | J15: 0.14496439 | K15: 5189 | L15: 0.15259884 | M15: 5336 | N15: 0.028329158 | O15: 5215 | P15: -0.022676162 | Q15: 4872 | R15: -0.065771812 | S15: 4439 | T15: -0.088875205 | U15: 4055 | V15: -0.08650597 | W15: 3613 | X15: -0.10900123 | Y15: 3637 | Z15: 0.0066426792 | AA15: 4153 | AB15: 0.14187517 | AC15: 4542.12 | AD15: 0.093696123 | AE15: 4442 | AF15: -0.02204257 | AG15: 4379 | AH15: -0.014182801 | AI15: 4293 | AJ15: -0.019639187 | AK15: 4190 | AL15: -0.023992546 | AM15: 3973 | AN15: -0.051789976 | AO15: 4204 | AP15: 0.058142462 | AQ15: 4348 | AR15: 0.034253092 | AS15: 4211 | AT15: -0.03150874 | AU15: 4120 | AV15: -0.021610069 | AW15: 3707 | AX15: -0.10024272 | AY15: 3960 | AZ15: 0.068249258 | BA15: 3645 | BB15: -0.079545455 | BC15: 3243 | BD15: -0.11028807 | BE15: 3657 | BF15: 0.12765957 | BG15: 4314 | BH15: 0.17965546 | BI15: 4756 | BJ15: 0.10245712 | BK15: 4923 | BL15: 0.035113541 | BM15: 5460 | BN15: 0.10907983 | BO15: 5771 | BP15: 0.056959707 | BQ15: 5673 | BR15: -0.016981459 | BS15: 5370 | BT15: -0.053410894 | BU15: 5119 | BV15: -0.046741155 | BW15: 5405 | BX15: 0.055870287 | BY15: 5717 | BZ15: 0.057724329 | CA15: 5388 | CB15: -0.057547665 | CC15: 5285 | CD15: -0.019116555 | CE15: 5051 | CF15: -0.044276254 | CG15: 4622 | CH15: -0.084933676 | CI15: 4380 | CJ15: -0.052358286 | CK15: 4094 | CL15: -0.065296804 | CM15: 3999 | CN15: -0.02320469 | CO15: 4053 | CP15: 0.013503376 | CQ15: 3755 | CR15: -0.073525783 | CS15: 3732 | CT15: -0.0061251664 | CU15: 4250 | CV15: 0.13879957 | CW15: 4542 | CX15: 0.068705882 | CY15: 4679 | CZ15: 0.030162924 | DA15: 4600 | DB15: -0.01688395 | DC15: 4675 | DD15: 0.016304348 | DE15: 4690 | DF15: 0.0032085561 | DG15: 4759 | DH15: 0.014712154 | DI15: 4950 | DJ15: 0.040134482 | DK15: 5019.37 | DL15: 0.014014141 | DM15: 4879 | DN15: -0.027965661 | DO15: 4313 | DP15: -0.11600738 | DQ15: 3764 | DR15: -0.12728959 | DS15: 4001 | DT15: 0.062964931 | DU15: 4041 | DV15: 0.0099975006 | DW15: 3947 | DX15: -0.023261569 | DY15: 4015 | DZ15: 0.017228275 | EA15: 3693 | EB15: -0.080199253 | EC15: 3867 | ED15: 0.047116166 | EE15: 3801 | EF15: -0.017067494
B16: Южный | C16: 5316 | D16: 0 | E16: 5279 | F16: -0.0069601204 | G16: 3709 | H16: -0.29740481 | I16: 4080 | J16: 0.10002696 | K16: 4808 | L16: 0.17843137 | M16: 4750 | N16: -0.012063228 | O16: 4644 | P16: -0.022315789 | Q16: 4584 | R16: -0.012919897 | S16: 4262 | T16: -0.070244328 | U16: 3817 | V16: -0.10441107 | W16: 3383 | X16: -0.11370186 | Y16: 3273 | Z16: -0.032515519 | AA16: 3613 | AB16: 0.10388023 | AC16: 4056.3 | AD16: 0.12269582 | AE16: 4012 | AF16: -0.010921283 | AG16: 4106 | AH16: 0.023429711 | AI16: 4265 | AJ16: 0.038723819 | AK16: 4278 | AL16: 0.0030480657 | AM16: 4053 | AN16: -0.05259467 | AO16: 4134.06 | AP16: 0.02 | AQ16: 4258 | AR16: 0.029980213 | AS16: 3965 | AT16: -0.068811649 | AU16: 3864 | AV16: -0.025472888 | AW16: 3497 | AX16: -0.094979296 | AY16: 4004 | AZ16: 0.14498141 | BA16: 3818 | BB16: -0.046453546 | BC16: 3297 | BD16: -0.13645888 | BE16: 3710 | BF16: 0.12526539 | BG16: 4269 | BH16: 0.15067385 | BI16: 4581 | BJ16: 0.073085032 | BK16: 4833 | BL16: 0.055009823 | BM16: 5354 | BN16: 0.10780054 | BO16: 5459 | BP16: 0.019611505 | BQ16: 5331 | BR16: -0.023447518 | BS16: 5019 | BT16: -0.058525605 | BU16: 4865 | BV16: -0.030683403 | BW16: 5112 | BX16: 0.050770812 | BY16: 5483 | BZ16: 0.072574335 | CA16: 5270 | CB16: -0.038847346 | CC16: 5150 | CD16: -0.022770398 | CE16: 4985 | CF16: -0.032038835 | CG16: 4632 | CH16: -0.070812437 | CI16: 4444 | CJ16: -0.040587219 | CK16: 4067 | CL16: -0.084833483 | CM16: 3960 | CN16: -0.026309319 | CO16: 4057 | CP16: 0.024494949 | CQ16: 3797 | CR16: -0.064086764 | CS16: 3757 | CT16: -0.010534633 | CU16: 4116 | CV16: 0.095554964 | CW16: 4422 | CX16: 0.074344023 | CY16: 4493 | CZ16: 0.016056083 | DA16: 4523 | DB16: 0.0066770532 | DC16: 4688 | DD16: 0.036480212 | DE16: 4627 | DF16: -0.013011945 | DG16: 4629 | DH16: 0.00043224552 | DI16: 4753 | DJ16: 0.026787643 | DK16: 4916.65 | DL16: 0.034430886 | DM16: 4773 | DN16: -0.029217048 | DO16: 4238 | DP16: -0.11208883 | DQ16: 3835 | DR16: -0.095092025 | DS16: 4035 | DT16: 0.052151239 | DU16: 3996 | DV16: -0.0096654275 | DW16: 3898 | DX16: -0.024524525 | DY16: 3987 | DZ16: 0.022832222 | EA16: 3796 | EB16: -0.047905694 | EC16: 3939 | ED16: 0.037671233 | EE16: 3865 | EF16: -0.018786494
B17: Зеленоградский АО | C17: 0 | D17: 0 | E17: 0 | F17: 0 | G17: 0 | H17: 0 | I17: 0 | J17: 0 | K17: 0 | L17: 0 | M17: 0 | N17: 0 | O17: 0 | P17: 0 | Q17: 0 | R17: 0 | S17: 0 | T17: 0 | U17: 0 | V17: 0 | W17: 0 | X17: 0 | Y17: 0 | Z17: 0 | AA17: 0 | AB17: 0 | AC17: 0 | AD17: 0 | AE17: 0 | AF17: 0 | AG17: 0 | AH17: 0 | AI17: 0 | AJ17: 0 | AK17: 0 | AL17: 0 | AM17: 0 | AN17: 0 | AO17: 442 | AP17: 0 | AQ17: 467 | AR17: 0.056561086 | AS17: 455 | AT17: -0.025695931 | AU17: 0 | AV17: -1 | AW17: 458 | AX17: 0 | AY17: 518 | AZ17: 0.13100437 | BA17: 542 | BB17: 0.046332046 | BC17: 494 | BD17: -0.088560886 | BE17: 501 | BF17: 0.01417004 | BG17: 605 | BH17: 0.20758483 | BI17: 664 | BJ17: 0.097520661 | BK17: 703 | BL17: 0.05873494 | BM17: 752 | BN17: 0.06970128 | BO17: 772 | BP17: 0.026595745 | BQ17: 739 | BR17: -0.042746114 | BS17: 691 | BT17: -0.064952639 | BU17: 686 | BV17: -0.00723589 | BW17: 737 | BX17: 0.074344023 | BY17: 755 | BZ17: 0.024423338 | CA17: 697 | CB17: -0.076821192 | CC17: 686 | CD17: -0.015781923 | CE17: 639 | CF17: -0.06851312 | CG17: 580 | CH17: -0.092331768 | CI17: 536 | CJ17: -0.075862069 | CK17: 484 | CL17: -0.097014925 | CM17: 455 | CN17: -0.059917355 | CO17: 458 | CP17: 0.0065934066 | CQ17: 431 | CR17: -0.058951965 | CS17: 455 | CT17: 0.055684455 | CU17: 501 | CV17: 0.1010989 | CW17: 586 | CX17: 0.16966068 | CY17: 566 | CZ17: -0.034129693 | DA17: 599 | DB17: 0.058303887 | DC17: 605 | DD17: 0.010016694 | DE17: 575 | DF17: -0.049586777 | DG17: 585 | DH17: 0.017391304 | DI17: 614 | DJ17: 0.04957265 | DK17: 636.65 | DL17: 0.036889251 | DM17: 683 | DN17: 0.072802953 | DO17: 583 | DP17: -0.14641288 | DQ17: 538 | DR17: -0.077186964 | DS17: 566 | DT17: 0.05204461 | DU17: 593 | DV17: 0.04770318 | DW17: 562 | DX17: -0.05227656 | DY17: 534 | DZ17: -0.049822064 | EA17: 491 | EB17: -0.080524345 | EC17: 518 | ED17: 0.054989817 | EE17: 522 | EF17: 0.0077220077
B18: Итог | C18: =SUM(C6:C17) -> 51138 | D18: =SUM(C6:C17)/SUM(A6:A17)-1 -> #DIV/0! | E18: =SUM(E6:E17) -> 49623 | F18: =SUM(E6:E17)/SUM(C6:C17)-1 -> -0.029625719 | G18: =SUM(G6:G17) -> 35935 | H18: =SUM(G6:G17)/SUM(E6:E17)-1 -> -0.27583983 | I18: =SUM(I6:I17) -> 40051 | J18: =SUM(I6:I17)/SUM(G6:G17)-1 -> 0.11454014 | K18: =SUM(K6:K17) -> 45138 | L18: =SUM(K6:K17)/SUM(I6:I17)-1 -> 0.12701306 | M18: =SUM(M6:M17) -> 44816 | N18: =SUM(M6:M17)/SUM(K6:K17)-1 -> -0.0071336789 | O18: =SUM(O6:O17) -> 43874 | P18: =SUM(O6:O17)/SUM(M6:M17)-1 -> -0.021019279 | Q18: =SUM(Q6:Q17) -> 42617 | R18: =SUM(Q6:Q17)/SUM(O6:O17)-1 -> -0.028650226 | S18: =SUM(S6:S17) -> 40044 | T18: =SUM(S6:S17)/SUM(Q6:Q17)-1 -> -0.060374968 | U18: =SUM(U6:U17) -> 36531 | V18: =SUM(U6:U17)/SUM(S6:S17)-1 -> -0.087728499 | W18: =SUM(W6:W17) -> 33045 | X18: =SUM(W6:W17)/SUM(U6:U17)-1 -> -0.095425803 | Y18: =SUM(Y6:Y17) -> 33696 | Z18: =SUM(Y6:Y17)/SUM(W6:W17)-1 -> 0.019700409 | AA18: =SUM(AA6:AA17) -> 36928 | AB18: =SUM(AA6:AA17)/SUM(Y6:Y17)-1 -> 0.095916429 | AC18: =SUM(AC6:AC17) -> 40098.84 | AD18: =SUM(AC6:AC17)/SUM(AA6:AA17)-1 -> 0.085865468 | AE18: =SUM(AE6:AE17) -> 39674 | AF18: =SUM(AE6:AE17)/SUM(AC6:AC17)-1 -> -0.01059482 | AG18: =SUM(AG6:AG17) -> 39139 | AH18: =SUM(AG6:AG17)/SUM(AE6:AE17)-1 -> -0.013484902 | AI18: =SUM(AI6:AI17) -> 39250 | AJ18: =SUM(AI6:AI17)/SUM(AG6:AG17)-1 -> 0.0028360459 | AK18: =SUM(AK6:AK17) -> 38946 | AL18: =SUM(AK6:AK17)/SUM(AI6:AI17)-1 -> -0.0077452229 | AM18: =SUM(AM6:AM17) -> 37677 | AN18: =SUM(AM6:AM17)/SUM(AK6:AK17)-1 -> -0.032583577 | AO18: =SUM(AO6:AO17) -> 39371.87 | AP18: =SUM(AO6:AO17)/SUM(AM6:AM17)-1 -> 0.044984208 | AQ18: =SUM(AQ6:AQ17) -> 40320 | AR18: =SUM(AQ6:AQ17)/SUM(AO6:AO17)-1 -> 0.024081406 | AS18: =SUM(AS6:AS17) -> 38654 | AT18: =SUM(AS6:AS17)/SUM(AQ6:AQ17)-1 -> -0.041319444 | AU18: =SUM(AU6:AU17) -> 36939 | AV18: =SUM(AU6:AU17)/SUM(AS6:AS17)-1 -> -0.044367983 | AW18: =SUM(AW6:AW17) -> 34055 | AX18: =SUM(AW6:AW17)/SUM(AU6:AU17)-1 -> -0.078074664 | AY18: =SUM(AY6:AY17) -> 37351 | AZ18: =SUM(AY6:AY17)/SUM(AW6:AW17)-1 -> 0.096784613 | BA18: =SUM(BA6:BA17) -> 35749 | BB18: =SUM(BA6:BA17)/SUM(AY6:AY17)-1 -> -0.042890418 | BC18: =SUM(BC6:BC17) -> 32227 | BD18: =SUM(BC6:BC17)/SUM(BA6:BA17)-1 -> -0.098520238 | BE18: =SUM(BE6:BE17) -> 35606 | BF18: =SUM(BE6:BE17)/SUM(BC6:BC17)-1 -> 0.10484997 | BG18: =SUM(BG6:BG17) -> 40367 | BH18: =SUM(BG6:BG17)/SUM(BE6:BE17)-1 -> 0.13371342 | BI18: =SUM(BI6:BI17) -> 43364 | BJ18: =SUM(BI6:BI17)/SUM(BG6:BG17)-1 -> 0.074243813 | BK18: =SUM(BK6:BK17) -> 44486 | BL18: =SUM(BK6:BK17)/SUM(BI6:BI17)-1 -> 0.025873997 | BM18: =SUM(BM6:BM17) -> 49091 | BN18: =SUM(BM6:BM17)/SUM(BK6:BK17)-1 -> 0.10351571 | BO18: =SUM(BO6:BO17) -> 50851 | BP18: =SUM(BO6:BO17)/SUM(BM6:BM17)-1 -> 0.035851785 | BQ18: =SUM(BQ6:BQ17) -> 50186 | BR18: =SUM(BQ6:BQ17)/SUM(BO6:BO17)-1 -> -0.013077422 | BS18: =SUM(BS6:BS17) -> 48354 | BT18: =SUM(BS6:BS17)/SUM(BQ6:BQ17)-1 -> -0.036504204 | BU18: =SUM(BU6:BU17) -> 46290 | BV18: =SUM(BU6:BU17)/SUM(BS6:BS17)-1 -> -0.042685197 | BW18: =SUM(BW6:BW17) -> 48705 | BX18: =SUM(BW6:BW17)/SUM(BU6:BU17)-1 -> 0.052171095 | BY18: =SUM(BY6:BY17) -> 51354 | BZ18: =SUM(BY6:BY17)/SUM(BW6:BW17)-1 -> 0.054388666 | CA18: =SUM(CA6:CA17) -> 48817 | CB18: =SUM(CA6:CA17)/SUM(BY6:BY17)-1 -> -0.049402189 | CC18: =SUM(CC6:CC17) -> 47660 | CD18: =SUM(CC6:CC17)/SUM(CA6:CA17)-1 -> -0.02370076 | CE18: =SUM(CE6:CE17) -> 46252 | CF18: =SUM(CE6:CE17)/SUM(CC6:CC17)-1 -> -0.029542593 | CG18: =SUM(CG6:CG17) -> 43280 | CH18: =SUM(CG6:CG17)/SUM(CE6:CE17)-1 -> -0.064256681 | CI18: =SUM(CI6:CI17) -> 41050 | CJ18: =SUM(CI6:CI17)/SUM(CG6:CG17)-1 -> -0.051524954 | CK18: =SUM(CK6:CK17) -> 38632 | CL18: =SUM(CK6:CK17)/SUM(CI6:CI17)-1 -> -0.058903776 | CM18: =SUM(CM6:CM17) -> 37552 | CN18: =SUM(CM6:CM17)/SUM(CK6:CK17)-1 -> -0.027956099 | CO18: =SUM(CO6:CO17) -> 37865 | CP18: =SUM(CO6:CO17)/SUM(CM6:CM17)-1 -> 0.0083351086 | CQ18: =SUM(CQ6:CQ17) -> 34799 | CR18: =SUM(CQ6:CQ17)/SUM(CO6:CO17)-1 -> -0.080971874 | CS18: =SUM(CS6:CS17) -> 34722 | CT18: =SUM(CS6:CS17)/SUM(CQ6:CQ17)-1 -> -0.0022127073 | CU18: =SUM(CU6:CU17) -> 38847 | CV18: =SUM(CU6:CU17)/SUM(CS6:CS17)-1 -> 0.11880076 | CW18: =SUM(CW6:CW17) -> 40695 | CX18: =SUM(CW6:CW17)/SUM(CU6:CU17)-1 -> 0.047571241 | CY18: =SUM(CY6:CY17) -> 41463 | CZ18: =SUM(CY6:CY17)/SUM(CW6:CW17)-1 -> 0.018872097 | DA18: =SUM(DA6:DA17) -> 41191 | DB18: =SUM(DA6:DA17)/SUM(CY6:CY17)-1 -> -0.0065600656 | DC18: =SUM(DC6:DC17) -> 42751 | DD18: =SUM(DC6:DC17)/SUM(DA6:DA17)-1 -> 0.037872351 | DE18: =SUM(DE6:DE17) -> 43920 | DF18: =SUM(DE6:DE17)/SUM(DC6:DC17)-1 -> 0.02734439 | DG18: =SUM(DG6:DG17) -> 44771 | DH18: =SUM(DG6:DG17)/SUM(DE6:DE17)-1 -> 0.019376138 | DI18: =SUM(DI6:DI17) -> 45297 | DJ18: =SUM(DI6:DI17)/SUM(DG6:DG17)-1 -> 0.011748677 | DK18: =SUM(DK6:DK17) -> 46503.27 | DL18: =SUM(DK6:DK17)/SUM(DI6:DI17)-1 -> 0.02663024 | DM18: =SUM(DM6:DM17) -> 45781 | DN18: =SUM(DM6:DM17)/SUM(DK6:DK17)-1 -> -0.015531596 | DO18: =SUM(DO6:DO17) -> 40105 | DQ18: =SUM(DQ6:DQ17) -> 35988 | DS18: =SUM(DS6:DS17) -> 37022 | DT18: =DS18/DQ18-1 -> 0.028731799 | DU18: =SUM(DU6:DU17) -> 37437 | DW18: =SUM(DW6:DW17) -> 36697 | DX18: =DW18/DU18-1 -> -0.019766541
B20: Изменение средней цены относительно прошлого месяца
C22: Год | D22: Период | E22: Значения
C23: 2020 | Y23: 2021 | AW23: 2022 | BU23: 2023 | CS23: 2024 | DQ23: 2025
C24: фев | E24: мар | G24: апр | I24: май | K24: июн | M24: июл | O24: авг | Q24: сен | S24: окт | U24: ноя | W24: дек | Y24: янв | AA24: фев | AC24: мар | AE24: апр | AG24: май | AI24: июн | AK24: июл | AM24: авг | AO24: сен | AQ24: окт | AS24: ноя | AU24: дек | AW24: янв | AY24: фев | BA24: мар | BC24: апр | BE24: май | BG24: июн | BI24: июл | BK24: авг | BM24: сен | BO24: окт | BQ24: ноя | BS24: дек | BU24: янв | BW24: фев | BY24: мар | CA24: апр | CC24: май | CE24: июн | CG24: июл | CI24: авг | CK24: сен | CM24: окт | CO24: ноя | CQ24: дек | CS24: янв | CU24: фев | CW24: мар | CY24: апр | DA24: май | DC24: июн | DE24: июл | DG24: авг | DI24: сен | DK24: окт | DM24: ноя | DO24: дек | DQ24: янв | DS24: фев | DU24: мар | DW24: апр | DY24: май | EA24: июн | EC24: июл | EE24: авг
B25: Округ | C25: Цена | D25: Изменение | E25: Цена | F25: Изменение | G25: Цена | H25: Изменение | I25: Цена | J25: Изменение | K25: Цена | L25: Изменение | M25: Цена | N25: Изменение | O25: Цена | P25: Изменение | Q25: Цена | R25: Изменение | S25: Цена | T25: Изменение | U25: Цена | V25: Изменение | W25: Цена | X25: Изменение | Y25: Цена | Z25: Изменение | AA25: Цена | AB25: Изменение | AC25: Цена | AD25: Изменение | AE25: Цена | AF25: Изменение | AG25: Цена | AH25: Изменение | AI25: Цена | AJ25: Изменение | AK25: Цена | AL25: Изменение | AM25: Цена | AN25: Изменение | AO25: Цена | AP25: Изменение | AQ25: Цена | AR25: Изменение | AS25: Цена | AT25: Изменение | AU25: Цена | AV25: Изменение | AW25: Цена | AX25: Изменение | AY25: Цена | AZ25: Изменение | BA25: Цена | BB25: Изменение | BC25: Цена | BD25: Изменение | BE25: Цена | BF25: Изменение | BG25: Цена | BH25: Изменение | BI25: Цена | BJ25: Изменение | BK25: Цена | BL25: Изменение | BM25: Цена | BN25: Изменение | BO25: Цена | BP25: Изменение | BQ25: Цена | BR25: Изменение | BS25: Цена | BT25: Изменение | BU25: Цена | BV25: Изменение | BW25: Цена | BX25: Изменение | BY25: Цена | BZ25: Изменение | CA25: Цена | CB25: Изменение | CC25: Цена | CD25: Изменение | CE25: Цена | CF25: Изменение | CG25: Цена | CH25: Изменение | CI25: Цена | CJ25: Изменение | CK25: Цена | CL25: Изменение | CM25: Цена | CN25: Изменение | CO25: Цена | CP25: Изменение | CQ25: Цена | CR25: Изменение | CS25: Цена | CT25: Изменение | CU25: Цена | CV25: Изменение | CW25: Цена | CX25: Изменение | CY25: Цена | CZ25: Изменение | DA25: Цена | DB25: Изменение | DC25: Цена | DD25: Изменение | DE25: Цена | DF25: Изменение | DG25: Цена | DH25: Изменение | DI25: Цена | DJ25: Изменение | DK25: Цена | DL25: Изменение | DM25: Цена | DN25: Изменение | DO25: Цена | DP25: Изменение | DQ25: Цена | DR25: Изменение | DS25: Цена | DT25: Изменение | DU25: Цена | DV25: Изменение | DW25: Цена | DX25: Изменение | DY25: Цена | DZ25: Изменение | EA25: Цена | EB25: Изменение | EC25: Цена | ED25: Изменение | EE25: Цена | EF25: Изменение
B26: Восточный | C26: 186881.6 | D26: 0 | E26: 189676.17 | F26: 0.01495369 | G26: 193065.69 | H26: 0.017870057 | I26: 193645.08 | J26: 0.0030009626 | K26: 193154.91 | L26: -0.0025312694 | M26: 193771.53 | N26: 0.0031923828 | O26: 196359.5 | P26: 0.013355792 | Q26: 201082.52 | R26: 0.024052918 | S26: 207111.72 | T26: 0.029983711 | U26: 213064 | V26: 0.028739448 | W26: 217457.93 | X26: 0.020622565 | Y26: 222408.36 | Z26: 0.022765035 | AA26: 224060 | AB26: 0.0074261439 | AC26: 229760.21 | AD26: 0.025440529 | AE26: 231824.1 | AF26: 0.0089828356 | AG26: 236146.75 | AH26: 0.018646249 | AI26: 230983.15 | AJ26: -0.021866064 | AK26: 239462 | AL26: 0.036707642 | AM26: 243817.9 | AN26: 0.018190378 | AO26: 249485.84 | AP26: 0.023246609 | AQ26: 253346.33 | AR26: 0.01547376 | AS26: 256232 | AT26: 0.011390228 | AU26: 258976.4 | AV26: 0.010710623 | AW26: 267946.63 | AX26: 0.034637238 | AY26: 270974.11 | AZ26: 0.01129882 | BA26: 278463.86 | BB26: 0.027640091 | BC26: 280226.02 | BD26: 0.006328138 | BE26: 275858.13 | BF26: -0.015587036 | BG26: 272522.22 | BH26: -0.012092821 | BI26: 269980.53 | BJ26: -0.009326546 | BK26: 268038.25 | BL26: -0.0071941734 | BM26: 266117.44 | BN26: -0.0071661782 | BO26: 261889.19 | BP26: -0.015888652 | BQ26: 258588.98 | BR26: -0.012601558 | BS26: 258297.77 | BT26: -0.0011261487 | BU26: 259332.92 | BV26: 0.0040076061 | BW26: 259473.59 | BX26: 0.00054240138 | BY26: 259217.51 | BZ26: -0.00098688851 | CA26: 260149.97 | CB26: 0.0035971862 | CC26: 262704.28 | CD26: 0.0098186286 | CE26: 265501.57 | CF26: 0.010648031 | CG26: 266289.45 | CH26: 0.0029675212 | CI26: 271753.43 | CJ26: 0.020518963 | CK26: 277235.93 | CL26: 0.020174547 | CM26: 282293.97 | CN26: 0.018244531 | CO26: 283897.25 | CP26: 0.0056794587 | CQ26: 284566.58 | CR26: 0.0023576493 | CS26: 289262.51 | CT26: 0.016502056 | CU26: 289294.04 | CV26: 0.00010897294 | CW26: 288247.75 | CX26: -0.0036166761 | CY26: 288479.34 | CZ26: 0.0008034322 | DA26: 288968.1 | DB26: 0.0016942779 | DC26: 287676.33 | DD26: -0.0044703158 | DE26: 286793.21 | DF26: -0.0030698211 | DG26: 286025.57 | DH26: -0.002676629 | DI26: 287409.28 | DJ26: 0.0048377131 | DK26: 288992.82 | DL26: 0.0055097121 | DM26: 289091.93 | DN26: 0.00034294579 | DO26: 289980.25 | DP26: 0.0030727857 | DQ26: 292003.79 | DR26: 0.006978184 | DS26: 295857.64 | DT26: 0.013197945 | DU26: 296711.33 | DV26: 0.002885503 | DW26: 297368.21 | DX26: 0.0022138529 | DY26: 299179.83 | DZ26: 0.0060921908 | EA26: 300411.15 | EB26: 0.0041156458 | EC26: 301769.61 | ED26: 0.0045220012 | EE26: 301401.54 | EF26: -0.0012197246
B27: Западный | C27: 250628.75 | D27: 0 | E27: 253823.23 | F27: 0.012745861 | G27: 271405.14 | H27: 0.069268309 | I27: 262902.17 | J27: -0.031329447 | K27: 258806.72 | L27: -0.015577826 | M27: 259270.84 | N27: 0.0017933116 | O27: 261062.06 | P27: 0.006908659 | Q27: 267512.8 | R27: 0.024709605 | S27: 274968.23 | T27: 0.027869453 | U27: 284145.07 | V27: 0.033374177 | W27: 285015.18 | X27: 0.0030621859 | Y27: 288669.42 | Z27: 0.012821209 | AA27: 290704 | AB27: 0.0070481437 | AC27: 294686.3 | AD27: 0.013698815 | AE27: 299003.2 | AF27: 0.014649129 | AG27: 303562.77 | AH27: 0.015249248 | AI27: 307644.75 | AJ27: 0.013446885 | AK27: 307365.88 | AL27: -0.00090646884 | AM27: 313986.36 | AN27: 0.021539417 | AO27: 318405.33 | AP27: 0.014073768 | AQ27: 321496.05 | AR27: 0.0097068788 | AS27: 326170 | AT27: 0.014538125 | AU27: 330302.86 | AV27: 0.01267088 | AW27: 340527.34 | AX27: 0.030954851 | AY27: 346948.19 | AZ27: 0.018855607 | BA27: 363085.51 | BB27: 0.046512196 | BC27: 367420.53 | BD27: 0.011939388 | BE27: 359294.43 | BF27: -0.022116621 | BG27: 348500.66 | BH27: -0.030041577 | BI27: 343912.83 | BJ27: -0.013164459 | BK27: 340004.23 | BL27: -0.011365101 | BM27: 336424.3 | BN27: -0.010529071 | BO27: 330306.84 | BP27: -0.018183752 | BQ27: 326518.67 | BR27: -0.011468661 | BS27: 324768.07 | BT27: -0.0053613958 | BU27: 326279.83 | BV27: 0.0046548838 | BW27: 322496.15 | BX27: -0.011596429 | BY27: 325831.63 | BZ27: 0.010342698 | CA27: 326518.58 | CB27: 0.002108308 | CC27: 327429.41 | CD27: 0.002789521 | CE27: 328390.29 | CF27: 0.0029345973 | CG27: 333528.81 | CH27: 0.015647625 | CI27: 340731.1 | CJ27: 0.021594189 | CK27: 349255.28 | CL27: 0.025017342 | CM27: 352808.02 | CN27: 0.010172319 | CO27: 358307.04 | CP27: 0.015586442 | CQ27: 361334.58 | CR27: 0.0084495584 | CS27: 363757.26 | CT27: 0.0067048176 | CU27: 365488.46 | CV27: 0.0047592055 | CW27: 364124.99 | CX27: -0.0037305204 | CY27: 368219.19 | CZ27: 0.011243926 | DA27: 368799.48 | DB27: 0.0015759522 | DC27: 365693.23 | DD27: -0.008422605 | DE27: 365502.59 | DF27: -0.00052132594 | DG27: 365128.2 | DH27: -0.0010242964 | DI27: 363986.05 | DJ27: -0.0031280828 | DK27: 362538.3 | DL27: -0.0039774963 | DM27: 364445.73 | DN27: 0.0052613227 | DO27: 369502.28 | DP27: 0.013874619 | DQ27: 368329.73 | DR27: -0.0031733182 | DS27: 368955.45 | DT27: 0.0016988225 | DU27: 371943.62 | DV27: 0.0080989889 | DW27: 376505.27 | DX27: 0.012264354 | DY27: 379696.24 | DZ27: 0.0084752492 | EA27: 386488.58 | EB27: 0.017888872 | EC27: 382760.96 | ED27: -0.0096448385 | EE27: 390426.86 | EF27: 0.020027905
B28: Новомосковский | C28: 149719.02 | D28: 0 | E28: 149130.45 | F28: -0.0039311461 | G28: 149242.49 | H28: 0.0007512697 | I28: 149825.18 | J28: 0.0039043156 | K28: 150412.72 | L28: 0.0039215302 | M28: 152758.77 | N28: 0.015597412 | O28: 154507.02 | P28: 0.011444515 | Q28: 159503.02 | R28: 0.032335081 | S28: 163550.63 | T28: 0.025376434 | U28: 166987 | V28: 0.021011048 | W28: 168456 | X28: 0.0087970653 | Y28: 169893.75 | Z28: 0.0085348841 | AA28: 166469 | AB28: -0.020158201 | AC28: 170101.71 | AD28: 0.021822163 | AE28: 171331.38 | AF28: 0.007228996 | AG28: 185143.77 | AH28: 0.080617979 | AI28: 185631.43 | AJ28: 0.0026339838 | AK28: 189270 | AL28: 0.019601026 | AM28: 190978.59 | AN28: 0.009027287 | AO28: 191949.76 | AP28: 0.0050852242 | AQ28: 199505.42 | AR28: 0.039362665 | AS28: 204239.19 | AT28: 0.023727536 | AU28: 207782.73 | AV28: 0.01734994 | AW28: 209952.13 | AX28: 0.010440744 | AY28: 212581.94 | AZ28: 0.012525738 | BA28: 221724.67 | BB28: 0.04300803 | BC28: 224159.74 | BD28: 0.010982428 | BE28: 224950.52 | BF28: 0.0035277132 | BG28: 223068.02 | BH28: -0.0083685026 | BI28: 218829.21 | BJ28: -0.019002327 | BK28: 217394.8 | BL28: -0.0065549244 | BM28: 219142.34 | BN28: 0.0080385712 | BO28: 218235.14 | BP28: -0.0041397882 | BQ28: 213383.54 | BR28: -0.022231061 | BS28: 213351.93 | BT28: -0.00014811225 | BU28: 214267.88 | BV28: 0.0042931179 | BW28: 215088.57 | BX28: 0.0038302247 | BY28: 216997.25 | BZ28: 0.0088739126 | CA28: 216056.47 | CB28: -0.0043354509 | CC28: 213370.63 | CD28: -0.012431214 | CE28: 214974.23 | CF28: 0.0075155725 | CG28: 218059.79 | CH28: 0.014353188 | CI28: 220945.65 | CJ28: 0.013234228 | CK28: 224057.94 | CL28: 0.014086244 | CM28: 224930.66 | CN28: 0.0038950477 | CO28: 225511.97 | CP28: 0.0025843987 | CQ28: 225208.2 | CR28: -0.0013470095 | CS28: 227814.42 | CT28: 0.011572497 | CU28: 229921.29 | CV28: 0.0092481873 | CW28: 229030.49 | CX28: -0.0038743579 | CY28: 227357.98 | CZ28: -0.0073025823 | DA28: 226554.23 | DB28: -0.0035351911 | DC28: 237888.03 | DD28: 0.050026906 | DE28: 247623.3 | DF28: 0.040923749 | DG28: 246027.26 | DH28: -0.0064454603 | DI28: 240619.63 | DJ28: -0.021979778 | DK28: 241863.84 | DL28: 0.0051708539 | DM28: 244208.32 | DN28: 0.0096933986 | DO28: 238674.72 | DP28: -0.022659376 | DQ28: 240406.93 | DR28: 0.0072576165 | DS28: 239605.44 | DT28: -0.0033338671 | DU28: 241066.21 | DV28: 0.0060965609 | DW28: 240027.52 | DX28: -0.0043087232 | DY28: 240633.22 | DZ28: 0.0025234302 | EA28: 238893.67 | EB28: -0.0072290208 | EC28: 237231.21 | ED28: -0.0069590045 | EE28: 237173.08 | EF28: -0.00024505955
B29: Северный | C29: 219881.54 | D29: 0 | E29: 221727.09 | F29: 0.0083933588 | G29: 231120.58 | H29: 0.042365095 | I29: 226815.92 | J29: -0.018625146 | K29: 226938.58 | L29: 0.0005407685 | M29: 225564.81 | N29: -0.0060534948 | O29: 228416.83 | P29: 0.012643949 | Q29: 233369.73 | R29: 0.021683598 | S29: 240481.15 | T29: 0.030472765 | U29: 248660.82 | V29: 0.034013739 | W29: 249103.21 | X29: 0.0017791102 | Y29: 254214.56 | Z29: 0.020518986 | AA29: 250175 | AB29: -0.015890351 | AC29: 255178.5 | AD29: 0.02 | AE29: 262834 | AF29: 0.030000568 | AG29: 270519.52 | AH29: 0.029240974 | AI29: 271639.91 | AJ29: 0.0041416035 | AK29: 279829.87 | AL29: 0.030150083 | AM29: 285267.26 | AN29: 0.019431061 | AO29: 288234.29 | AP29: 0.010400855 | AQ29: 290471.22 | AR29: 0.0077608027 | AS29: 293787 | AT29: 0.011415186 | AU29: 298124.97 | AV29: 0.014765714 | AW29: 301307.6 | AX29: 0.010675487 | AY29: 306540.33 | AZ29: 0.017366715 | BA29: 320968.52 | BB29: 0.047067848 | BC29: 327258.35 | BD29: 0.019596393 | BE29: 321220.19 | BF29: -0.018450724 | BG29: 314573.91 | BH29: -0.020690751 | BI29: 308423.62 | BJ29: -0.019551168 | BK29: 308092.56 | BL29: -0.0010733943 | BM29: 307037.09 | BN29: -0.0034258305 | BO29: 301857.9 | BP29: -0.016868259 | BQ29: 298853.76 | BR29: -0.0099521962 | BS29: 296416.33 | BT29: -0.0081559289 | BU29: 296895.24 | BV29: 0.0016156707 | BW29: 297406.95 | BX29: 0.0017235357 | BY29: 298460.6 | BZ29: 0.0035428163 | CA29: 299938.94 | CB29: 0.0049532106 | CC29: 300379.37 | CD29: 0.0014684066 | CE29: 303225.99 | CF29: 0.0094767339 | CG29: 307368.1 | CH29: 0.013660154 | CI29: 314128.72 | CJ29: 0.021995175 | CK29: 321168.54 | CL29: 0.022410612 | CM29: 323237.11 | CN29: 0.0064407879 | CO29: 326254.4 | CP29: 0.009334604 | CQ29: 328426.97 | CR29: 0.0066591161 | CS29: 328810.33 | CT29: 0.0011672526 | CU29: 330143.53 | CV29: 0.0040546228 | CW29: 330494.81 | CX29: 0.0010640192 | CY29: 329507.2 | CZ29: -0.0029882688 | DA29: 329242.59 | DB29: -0.00080305739 | DC29: 330942.84 | DD29: 0.0051641248 | DE29: 330336.18 | DF29: -0.0018331245 | DG29: 331132.64 | DH29: 0.0024110647 | DI29: 330487.44 | DJ29: -0.0019484709 | DK29: 330183.05 | DL29: -0.00092103596 | DM29: 331672.09 | DN29: 0.0045097393 | DO29: 336113.4 | DP29: 0.013390661 | DQ29: 338682.92 | DR29: 0.0076448127 | DS29: 338936 | DT29: 0.00074724755 | DU29: 341724.36 | DV29: 0.0082268038 | DW29: 343250.62 | DX29: 0.0044663642 | DY29: 344838.07 | DZ29: 0.0046247416 | EA29: 344945.8 | EB29: 0.00031241056 | EC29: 347418.75 | ED29: 0.0071691026 | EE29: 348719.97 | EF29: 0.0037453717
B30: Северо-Восточный | C30: 195689.13 | D30: 0 | E30: 199279.43 | F30: 0.018346947 | G30: 203485.71 | H30: 0.021107426 | I30: 204127.92 | J30: 0.0031560466 | K30: 204628.72 | L30: 0.0024533493 | M30: 205183.9 | N30: 0.0027131163 | O30: 208545.58 | P30: 0.016383782 | Q30: 212295.61 | R30: 0.017981784 | S30: 218383.83 | T30: 0.028678027 | U30: 224126.57 | V30: 0.026296578 | W30: 227430 | X30: 0.01473912 | Y30: 226980.95 | Z30: -0.0019744719 | AA30: 227817 | AB30: 0.0036833604 | AC30: 230654 | AD30: 0.012452978 | AE30: 232671 | AF30: 0.0087446999 | AG30: 242760 | AH30: 0.043361657 | AI30: 250087.88 | AJ30: 0.030185692 | AK30: 258704 | AL30: 0.034452375 | AM30: 262066.97 | AN30: 0.012999305 | AO30: 267543.33 | AP30: 0.020896798 | AQ30: 271461.21 | AR30: 0.014643907 | AS30: 275176.25 | AT30: 0.013685319 | AU30: 279581.37 | AV30: 0.016008363 | AW30: 283948.77 | AX30: 0.01562123 | AY30: 287890.36 | AZ30: 0.013881336 | BA30: 296364.8 | BB30: 0.029436352 | BC30: 297827.46 | BD30: 0.0049353428 | BE30: 293393.43 | BF30: -0.014887942 | BG30: 294060.66 | BH30: 0.0022742093 | BI30: 288945.8 | BJ30: -0.017393901 | BK30: 286930.18 | BL30: -0.0069757754 | BM30: 285504.27 | BN30: -0.0049695494 | BO30: 281794.2 | BP30: -0.01299479 | BQ30: 278597.23 | BR30: -0.011345039 | BS30: 275840.22 | BT30: -0.0098960381 | BU30: 275615.1 | BV30: -0.00081612192 | BW30: 276820.28 | BX30: 0.0043726592 | BY30: 277437.93 | BZ30: 0.0022312638 | CA30: 277858.92 | CB30: 0.0015173932 | CC30: 279150.4 | CD30: 0.0046479854 | CE30: 279539.77 | CF30: 0.001394852 | CG30: 284347.04 | CH30: 0.017197054 | CI30: 291580.61 | CJ30: 0.025439246 | CK30: 294447.35 | CL30: 0.009831726 | CM30: 297704.72 | CN30: 0.011062651 | CO30: 299211.43 | CP30: 0.0050610887 | CQ30: 301104.79 | CR30: 0.0063278341 | CS30: 303900.31 | CT30: 0.0092842233 | CU30: 304797.92 | CV30: 0.0029536156 | CW30: 305786.9 | CX30: 0.0032447149 | CY30: 303756.43 | CZ30: -0.006640158 | DA30: 302621.59 | DB30: -0.0037360001 | DC30: 303820.54 | DD30: 0.0039618667 | DE30: 305159.31 | DF30: 0.0044064622 | DG30: 304370.83 | DH30: -0.0025838295 | DI30: 304404.81 | DJ30: 0.00011162993 | DK30: 306631.18 | DL30: 0.0073138444 | DM30: 305179.86 | DN30: -0.0047331089 | DO30: 306243.98 | DP30: 0.0034868712 | DQ30: 310326.19 | DR30: 0.013329911 | DS30: 313831.97 | DT30: 0.011297101 | DU30: 316327.06 | DV30: 0.0079504005 | DW30: 314724.05 | DX30: -0.0050675804 | DY30: 315255.16 | DZ30: 0.0016875229 | EA30: 319672.09 | EB30: 0.014010665 | EC30: 321520.86 | ED30: 0.0057833232 | EE30: 321601.44 | EF30: 0.00025062422
